Workbook

Sheet 1. Tổng quan
A1: BỘ TỪ KHOÁ GOOGLE ADS: TRỒNG RĂNG IMPLANT | NHA KHOA PARIS
A2: Mục tiêu: tối đa số ca implant chốt được trên mỗi đồng ngân sách. Thứ tự ưu tiên: Doanh thu > Tỷ lệ chuyển đổi > LTV > Thương hiệu.
A3: Chú thích: ô nền vàng chữ xanh là giả định đầu vào, thay bằng số thực của NKP. Các ô còn lại là công thức.
A5: A. PHÂN BỔ NGÂN SÁCH THEO CHIẾN DỊCH
A6: Ngân sách Search/tháng (VND) | B6: 200000000 | C6: Ví dụ. Nguồn: giả định, thay bằng ngân sách được duyệt
A8: Chiến dịch | B8: Ưu tiên | C8: Vai trò trong hành trình | D8: Tỷ trọng ngân sách | E8: Ngân sách/tháng (VND) | F8: Ngân sách/ngày (VND) | G8: Số từ khoá
A9: NKP | Brand | Implant | B9: P1 | C9: Quyết định: chặn đối thủ trên tên NKP | D9: 0.08 | E9: =$B$6*D9 -> 16000000 | F9: =E9/30 -> 533333.33 | G9: =COUNTIF('2. Bộ từ khoá'!$B:$B,A9) -> 10
A10: NKP | Hot | Giá Implant | B10: P1 | C10: Sẵn sàng mua: đang so giá | D10: 0.22 | E10: =$B$6*D10 -> 44000000 | F10: =E10/30 -> 1466666.7 | G10: =COUNTIF('2. Bộ từ khoá'!$B:$B,A10) -> 14
A11: NKP | Hot | Địa điểm | B11: P1 | C11: Sẵn sàng mua: đang chọn nơi làm | D11: 0.15 | E11: =$B$6*D11 -> 30000000 | F11: =E11/30 -> 1000000 | G11: =COUNTIF('2. Bộ từ khoá'!$B:$B,A11) -> 14
A12: NKP | Hot | Toàn hàm | B12: P1 | C12: Ca giá trị cao nhất (All-on-4/6) | D12: 0.22 | E12: =$B$6*D12 -> 44000000 | F12: =E12/30 -> 1466666.7 | G12: =COUNTIF('2. Bộ từ khoá'!$B:$B,A12) -> 13
A13: NKP | Warm | Giải pháp Implant | B13: P2 | C13: Đã chọn implant, chưa chọn nơi | D13: 0.13 | E13: =$B$6*D13 -> 26000000 | F13: =E13/30 -> 866666.67 | G13: =COUNTIF('2. Bộ từ khoá'!$B:$B,A13) -> 14
A14: NKP | Warm | Hãng trụ | B14: P2 | C14: So sánh vật liệu và giá theo hãng | D14: 0.05 | E14: =$B$6*D14 -> 10000000 | F14: =E14/30 -> 333333.33 | G14: =COUNTIF('2. Bộ từ khoá'!$B:$B,A14) -> 7
A15: NKP | Research | Cân nhắc | B15: P3 | C15: Xử lý nỗi sợ, thu lead tư vấn | D15: 0.07 | E15: =$B$6*D15 -> 14000000 | F15: =E15/30 -> 466666.67 | G15: =COUNTIF('2. Bộ từ khoá'!$B:$B,A15) -> 10
A16: NKP | Cold | Vấn đề mất răng | B16: P4 | C16: Nuôi tệp remarketing | D16: 0.03 | E16: =$B$6*D16 -> 6000000 | F16: =E16/30 -> 200000 | G16: =COUNTIF('2. Bộ từ khoá'!$B:$B,A16) -> 7
A17: NKP | Test | Đối thủ | B17: P4 | C17: Thử nghiệm giành KH đối thủ | D17: 0.05 | E17: =$B$6*D17 -> 10000000 | F17: =E17/30 -> 333333.33 | G17: =COUNTIF('2. Bộ từ khoá'!$B:$B,A17) -> 3
A18: Tổng | D18: =SUM(D9:D17) -> 1 | E18: =SUM(E9:E17) -> 200000000 | F18: =SUM(F9:F17) -> 6666666.7 | G18: =SUM(G9:G17) -> 92
A20: Cấp ưu tiên | B20: Tỷ trọng ngân sách | C20: Ngân sách/tháng (VND) | D20: Quy tắc đấu thầu
A21: P1 | B21: =SUMIF($B$9:$B$17,A21,$D$9:$D$17) -> 0.67 | C21: =SUMIF($B$9:$B$17,A21,$E$9:$E$17) -> 134000000 | D21: Thắng vị trí đầu. Không để mất hiển thị vì ngân sách (IS lost budget < 10%)
A22: P2 | B22: =SUMIF($B$9:$B$17,A22,$D$9:$D$17) -> 0.18 | C22: =SUMIF($B$9:$B$17,A22,$E$9:$E$17) -> 36000000 | D22: Đấu thầu theo CPA mục tiêu. Mở rộng khi P1 đã bão hoà
A23: P3 | B23: =SUMIF($B$9:$B$17,A23,$D$9:$D$17) -> 0.07 | C23: =SUMIF($B$9:$B$17,A23,$E$9:$E$17) -> 14000000 | D23: Giá thầu thấp, có trần CPC. Mục tiêu: lead tư vấn và tệp remarketing
A24: P4 | B24: =SUMIF($B$9:$B$17,A24,$D$9:$D$17) -> 0.08 | C24: =SUMIF($B$9:$B$17,A24,$E$9:$E$17) -> 16000000 | D24: Ngân sách cố định. Cắt sau 4 tuần nếu không ra lead đạt chuẩn
A26: B. MÔ HÌNH PHỄU: TỪ NGÂN SÁCH ĐẾN DOANH THU
A27: Chỉ số | B27: Giá trị | C27: Ghi chú
A28: CPC trung bình (VND) | B28: 22000 | C28: Giả định. Cập nhật từ Keyword Planner hoặc tài khoản thực
A29: Tỷ lệ click → lead | B29: 0.08 | C29: Giả định. Lead = form + cuộc gọi ≥ 60 giây + chat Zalo có SĐT
A30: Tỷ lệ lead → đặt lịch | B30: 0.45 | C30: Giả định. Lấy từ Caresoft
A31: Tỷ lệ đến khám (show-up) | B31: 0.65 | C31: Giả định. Lấy từ Caresoft
A32: Tỷ lệ chốt ca | B32: 0.45 | C32: Giả định. Lấy từ báo cáo tư vấn tại chi nhánh
A33: Giá trị ca trung bình (VND) | B33: 30000000 | C33: Giả định. Pha trộn ca 1 răng và ca toàn hàm
A35: Click | B35: =IF(B28=0,0,B6/B28) -> 9090.9091 | C35: Công thức
A36: Lead | B36: =B35*B29 -> 727.27273 | C36: Công thức
A37: Lịch hẹn | B37: =B36*B30 -> 327.27273 | C37: Công thức
A38: Lượt đến khám | B38: =B37*B31 -> 212.72727 | C38: Công thức
A39: Ca chốt | B39: =B38*B32 -> 95.727273 | C39: Công thức
A40: Doanh thu (VND) | B40: =B39*B33 -> 2871818182 | C40: Công thức
A41: CPL (VND) | B41: =IF(B36=0,0,B6/B36) -> 275000 | C41: Công thức
A42: Chi phí / ca chốt (VND) | B42: =IF(B39=0,0,B6/B39) -> 2089268.8 | C42: Chỉ số quyết định ngân sách, không phải CPL
A43: ROAS | B43: =IF(B6=0,0,B40/B6) -> 14.359091 | C43: Công thức
A45: C. NGUYÊN TẮC VẬN HÀNH
A46: 1. Tiền đi theo ý định mua: chỉ chuyển ngân sách xuống P2-P4 khi P1 mất dưới 10% hiển thị do ngân sách.
...

Sheet 2. Bộ từ khoá
A1: STT | B1: Chiến dịch | C1: Nhóm quảng cáo | D1: Từ khoá | E1: Kiểu khớp | F1: Ưu tiên | G1: Giai đoạn hành trình | H1: Cạnh tranh dự kiến | I1: Landing page | J1: Thông điệp / CTA chính | K1: Lượng tìm kiếm/tháng (Keyword Planner) | L1: CPC đề xuất VND (Keyword Planner) | M1: Ghi chú
A2: 1 | B2: NKP | Brand | Implant | C2: Brand + Implant | D2: nha khoa paris implant | E2: Exact | F2: P1 | G2: Quyết định | H2: Thấp | I2: LP1 | J2: Đặt lịch khám implant, nhận kế hoạch điều trị | M2: Giữ Top IS ≥ 90%. CPC brand rẻ nhất tài khoản
A3: 2 | B3: NKP | Brand | Implant | C3: Brand + Implant | D3: nha khoa paris trồng răng | E3: Exact | F3: P1 | G3: Quyết định | H3: Thấp | I3: LP1 | J3: Đặt lịch khám implant, nhận kế hoạch điều trị
A4: 3 | B4: NKP | Brand | Implant | C4: Brand + Implant | D4: trồng răng implant nha khoa paris | E4: Phrase | F4: P1 | G4: Quyết định | H4: Thấp | I4: LP1 | J4: Đặt lịch khám implant, nhận kế hoạch điều trị
A5: 4 | B5: NKP | Brand | Implant | C5: Brand + Implant | D5: giá implant nha khoa paris | E5: Phrase | F5: P1 | G5: Quyết định | H5: Thấp | I5: LP2 | J5: Báo giá minh bạch theo hãng trụ + trả góp | M5: KH đã chọn NKP, chỉ còn so giá: dẫn thẳng trang giá
A6: 5 | B6: NKP | Brand | Implant | C6: Brand + Implant | D6: nha khoa paris cấy ghép implant | E6: Phrase | F6: P1 | G6: Quyết định | H6: Thấp | I6: LP1 | J6: Đặt lịch khám implant, nhận kế hoạch điều trị
A7: 6 | B7: NKP | Brand | Implant | C7: Brand chung | D7: nha khoa paris | E7: Exact | F7: P1 | G7: Quyết định | H7: Thấp | I7: LP1 | J7: Bác sĩ, chi nhánh, bảo hành | M7: Chặn đối thủ đấu thầu tên NKP
A8: 7 | B8: NKP | Brand | Implant | C8: Brand chung | D8: nha khoa paris hà nội | E8: Exact | F8: P1 | G8: Quyết định | H8: Thấp | I8: LP3 | J8: Chi nhánh gần nhất + giờ làm việc
A9: 8 | B9: NKP | Brand | Implant | C9: Brand chung | D9: nha khoa paris địa chỉ | E9: Phrase | F9: P1 | G9: Quyết định | H9: Thấp | I9: LP3 | J9: Chi nhánh gần nhất + giờ làm việc | M9: Bật asset địa điểm và cuộc gọi
A10: 9 | B10: NKP | Brand | Implant | C10: Brand chung | D10: nha khoa paris có tốt không | E10: Phrase | F10: P1 | G10: Quyết định | H10: Thấp | I10: LP1 | J10: Case thật, bác sĩ, đánh giá KH | M10: KH đang kiểm tra uy tín: đưa bằng chứng, không đưa khuyến mãi
A11: 10 | B11: NKP | Brand | Implant | C11: Brand chung | D11: nha khoa paris review | E11: Phrase | F11: P1 | G11: Quyết định | H11: Thấp | I11: LP1 | J11: Case thật, bác sĩ, đánh giá KH
A12: 11 | B12: NKP | Hot | Giá Implant | C12: Giá chung | D12: giá trồng răng implant | E12: Exact | F12: P1 | G12: Hot | H12: Rất cao | I12: LP2 | J12: Nhận báo giá theo tình trạng răng + lịch chụp CT | M12: Từ khoá tiền chính: ưu tiên ngân sách cao nhất
A13: 12 | B13: NKP | Hot | Giá Implant | C13: Giá chung | D13: giá trồng răng implant | E13: Phrase | F13: P1 | G13: Hot | H13: Rất cao | I13: LP2 | J13: Nhận báo giá theo tình trạng răng + lịch chụp CT
A14: 13 | B14: NKP | Hot | Giá Implant | C14: Giá chung | D14: trồng răng implant giá bao nhiêu | E14: Phrase | F14: P1 | G14: Hot | H14: Rất cao | I14: LP2 | J14: Nhận báo giá theo tình trạng răng + lịch chụp CT
A15: 14 | B15: NKP | Hot | Giá Implant | C15: Giá chung | D15: chi phí cấy ghép implant | E15: Phrase | F15: P1 | G15: Hot | H15: Cao | I15: LP2 | J15: Nhận báo giá theo tình trạng răng + lịch chụp CT
A16: 15 | B16: NKP | Hot | Giá Implant | C16: Giá chung | D16: bảng giá implant | E16: Phrase | F16: P1 | G16: Hot | H16: Cao | I16: LP2 | J16: Bảng giá theo hãng trụ, không phát sinh
A17: 16 | B17: NKP | Hot | Giá Implant | C17: Giá chung | D17: trồng 1 răng implant bao nhiêu tiền | E17: Phrase | F17: P1 | G17: Hot | H17: Cao | I17: LP2 | J17: Giá trọn gói 1 răng (trụ + abutment + sứ)
A18: 17 | B18: NKP | Hot | Giá Implant | C18: Giá chung | D18: giá cấy implant 1 răng | E18: Phrase | F18: P1 | G18: Hot | H18: Cao | I18: LP2 | J18: Giá trọn gói 1 răng (trụ + abutment + sứ)
A19: 18 | B19: NKP | Hot | Giá Implant | C19: Giá chung | D19: cấy ghép implant giá | E19: Phrase | F19: P1 | G19: Hot | H19: Cao | I19: LP2 | J19: Nhận báo giá theo tình trạng răng + lịch chụp CT
A20: 19 | B20: NKP | Hot | Giá Implant | C20: Trả góp & ưu đãi | D20: trồng răng implant trả góp | E20: Phrase | F20: P1 | G20: Hot | H20: Trung bình | I20: LP2 | J20: Trả góp, duyệt nhanh, chia nhỏ chi phí | M20: Nhóm chốt tốt: rào cản chính là tiền
A21: 20 | B21: NKP | Hot | Giá Implant | C21: Trả góp & ưu đãi | D21: implant trả góp lãi suất 0 | E21: Phrase | F21: P1 | G21: Hot | H21: Trung bình | I21: LP2 | J21: Trả góp, duyệt nhanh, chia nhỏ chi phí | M21: Chỉ chạy nếu có đối tác tài chính 0%
A22: 21 | B22: NKP | Hot | Giá Implant | C22: Trả góp & ưu đãi | D22: ưu đãi trồng răng implant | E22: Phrase | F22: P1 | G22: Hot | H22: Cao | I22: LP2 | J22: Ưu đãi có thời hạn + đặt lịch giữ suất
A23: 22 | B23: NKP | Hot | Giá Implant | C23: Trả góp & ưu đãi | D23: khuyến mãi cấy implant | E23: Phrase | F23: P1 | G23: Hot | H23: Cao | I23: LP2 | J23: Ưu đãi có thời hạn + đặt lịch giữ suất
A24: 23 | B24: NKP | Hot | Giá Implant | C24: Giá rẻ | D24: trồng răng implant giá rẻ | E24: Phrase | F24: P3 | G24: Hot | H24: Rất cao | I24: LP2 | J24: Gói tiêu chuẩn chất lượng + trả góp | M24: Tách riêng để kiểm soát. Đo theo chi phí/ca chốt, không theo CPL
A25: 24 | B25: NKP | Hot | Giá Implant | C25: Giá rẻ | D25: implant giá rẻ | E25: Phrase | F25: P3 | G25: Hot | H25: Rất cao | I25: LP2 | J25: Gói tiêu chuẩn chất lượng + trả góp | M25: Không hạ giá trên QC để kéo lead
A26: 25 | B26: NKP | Hot | Địa điểm | C26: Uy tín / ở đâu | D26: trồng răng implant ở đâu tốt | E26: Phrase | F26: P1 | G26: Hot | H26: Cao | I26: LP3 | J26: Gặp bác sĩ implant tại chi nhánh gần nhất
A27: 26 | B27: NKP | Hot | Địa điểm | C27: Uy tín / ở đâu | D27: nha khoa implant uy tín | E27: Phrase | F27: P1 | G27: Hot | H27: Rất cao | I27: LP3 | J27: Bác sĩ, số ca đã làm, bảo hành
A28: 27 | B28: NKP | Hot | Địa điểm | C28: Uy tín / ở đâu | D28: địa chỉ trồng răng implant uy tín | E28: Phrase | F28: P1 | G28: Hot | H28: Cao | I28: LP3 | J28: Gặp bác sĩ implant tại chi nhánh gần nhất
A29: 28 | B29: NKP | Hot | Địa điểm | C29: Uy tín / ở đâu | D29: bác sĩ cấy ghép implant giỏi | E29: Phrase | F29: P1 | G29: Hot | H29: Trung bình | I29: LP3 | J29: Hồ sơ bác sĩ + case thật | M29: Trigger quyết định: uy tín bác sĩ
A30: 29 | B30: NKP | Hot | Địa điểm | C30: Uy tín / ở đâu | D30: nha khoa cấy ghép implant | E30: Phrase | F30: P1 | G30: Hot | H30: Cao | I30: LP3 | J30: Gặp bác sĩ implant tại chi nhánh gần nhất
A31: 30 | B31: NKP | Hot | Địa điểm | C31: Gần đây | D31: trồng răng implant gần đây | E31: Phrase | F31: P1 | G31: Hot | H31: Cao | I31: LP3 | J31: Chi nhánh gần nhất, bấm gọi | M31: Bắt buộc bật asset địa điểm
A32: 31 | B32: NKP | Hot | Địa điểm | C32: Gần đây | D32: nha khoa implant gần đây | E32: Phrase | F32: P1 | G32: Hot | H32: Cao | I32: LP3 | J32: Chi nhánh gần nhất, bấm gọi
A33: 32 | B33: NKP | Hot | Địa điểm | C33: Hà Nội | D33: trồng răng implant hà nội | E33: Exact | F33: P1 | G33: Hot | H33: Rất cao | I33: LP3 | J33: Chi nhánh Hà Nội + bác sĩ | M33: Chỉ chạy nhóm tỉnh/thành có chi nhánh
A34: 33 | B34: NKP | Hot | Địa điểm | C34: Hà Nội | D34: trồng răng implant hà nội | E34: Phrase | F34: P1 | G34: Hot | H34: Rất cao | I34: LP3 | J34: Chi nhánh Hà Nội + bác sĩ
A35: 34 | B35: NKP | Hot | Địa điểm | C35: Hà Nội | D35: cấy ghép implant hà nội | E35: Phrase | F35: P1 | G35: Hot | H35: Cao | I35: LP3 | J35: Chi nhánh Hà Nội + bác sĩ
A36: 35 | B36: NKP | Hot | Địa điểm | C36: Hà Nội | D36: nha khoa implant hà nội | E36: Phrase | F36: P1 | G36: Hot | H36: Cao | I36: LP3 | J36: Chi nhánh Hà Nội + bác sĩ | M36: Mở rộng: trồng răng implant [tên quận]
A37: 36 | B37: NKP | Hot | Địa điểm | C37: TP.HCM | D37: trồng răng implant tphcm | E37: Phrase | F37: P1 | G37: Hot | H37: Rất cao | I37: LP3 | J37: Chi nhánh TP.HCM + bác sĩ
A38: 37 | B38: NKP | Hot | Địa điểm | C38: TP.HCM | D38: cấy ghép implant sài gòn | E38: Phrase | F38: P1 | G38: Hot | H38: Cao | I38: LP3 | J38: Chi nhánh TP.HCM + bác sĩ
A39: 38 | B39: NKP | Hot | Địa điểm | C39: TP.HCM | D39: nha khoa implant hcm | E39: Phrase | F39: P1 | G39: Hot | H39: Cao | I39: LP3 | J39: Chi nhánh TP.HCM + bác sĩ
A40: 39 | B40: NKP | Hot | Toàn hàm | C40: All-on-4 / 6 | D40: all on 4 | E40: Phrase | F40: P1 | G40: Hot | H40: Cao | I40: LP4 | J40: Tư vấn phục hình toàn hàm 1:1 với bác sĩ | M40: Ca giá trị cao nhất: được phép CPC cao hơn nhóm khác
...

Sheet 3. Từ khoá phủ định
A1: Nhóm | B1: Từ khoá phủ định | C1: Kiểu khớp | D1: Áp dụng ở | E1: Lý do
A2: A. Danh sách chung (cấp tài khoản: NKP_Neg_Chung)
A3: Học / nghề nghiệp | B3: khoá học | C3: Phrase | D3: Toàn tài khoản | E3: Bác sĩ, sinh viên tìm khoá học
A4: Học / nghề nghiệp | B4: học cấy ghép | C4: Phrase | D4: Toàn tài khoản | E4: Bác sĩ, sinh viên tìm khoá học
A5: Học / nghề nghiệp | B5: đào tạo | C5: Broad | D5: Toàn tài khoản | E5: Không phải bệnh nhân
A6: Học / nghề nghiệp | B6: tuyển dụng | C6: Broad | D6: Toàn tài khoản | E6: Người tìm việc
A7: Học / nghề nghiệp | B7: việc làm | C7: Broad | D7: Toàn tài khoản | E7: Người tìm việc
A8: Học / nghề nghiệp | B8: lương | C8: Broad | D8: Toàn tài khoản | E8: Người tìm việc
A9: Học / nghề nghiệp | B9: giáo trình | C9: Broad | D9: Toàn tài khoản | E9: Tài liệu học thuật
A10: Học / nghề nghiệp | B10: luận văn | C10: Broad | D10: Toàn tài khoản | E10: Tài liệu học thuật
A11: Học / nghề nghiệp | B11: pdf | C11: Broad | D11: Toàn tài khoản | E11: Tài liệu học thuật
A12: Khác dịch vụ | B12: implant ngực | C12: Phrase | D12: Toàn tài khoản | E12: Implant ngành thẩm mỹ ngực
A13: Khác dịch vụ | B13: nâng ngực | C13: Phrase | D13: Toàn tài khoản | E13: Implant ngành thẩm mỹ ngực
A14: Khác dịch vụ | B14: ốc tai | C14: Phrase | D14: Toàn tài khoản | E14: Implant tai mũi họng
... A36: Danh tiếng | B36: bóc phốt | C36: Broad | D36: Chiến dịch non-brand | E36: Như trên
A38: B. Phủ định chéo (điều hướng truy vấn về đúng chiến dịch)
A39: Đẩy truy vấn giá về chiến dịch Giá | B39: giá | C39: Broad | D39: Warm | Giải pháp, Warm | Hãng trụ (nhóm Theo hãng, trừ từ khoá có 'giá'), Research, Cold, Hot | Địa điểm | E39: Truy vấn có 'giá' phải vào LP2, nơi chuyển đổi cao nhất
A40: Đẩy truy vấn giá về chiến dịch Giá | B40: bao nhiêu tiền | C40: Phrase | D40: Warm | Giải pháp, Research, Cold, Hot | Địa điểm | E40: Như trên
A41: Đẩy truy vấn giá về chiến dịch Giá | B41: chi phí | C41: Broad | D41: Warm | Giải pháp, Research, Cold, Hot | Địa điểm | E41: Như trên
A42: Đẩy truy vấn giá về chiến dịch Giá | B42: bảng giá | C42: Phrase | D42: Warm | Giải pháp, Research, Cold, Hot | Địa điểm | E42: Như trên
A43: Đẩy truy vấn toàn hàm về chiến dịch Toàn hàm | B43: toàn hàm | C43: Phrase | D43: Hot | Giá, Hot | Địa điểm, Warm | Giải pháp, Research | E43: Ca giá trị cao cần LP4 và kịch bản tư vấn riêng
A44: Đẩy truy vấn toàn hàm về chiến dịch Toàn hàm | B44: all on | C44: Phrase | D44: Hot | Giá, Hot | Địa điểm, Warm | Giải pháp, Research | E44: Như trên
A45: Đẩy truy vấn toàn hàm về chiến dịch Toàn hàm | B45: người già | C45: Phrase | D45: Warm | Giải pháp, Research | E45: Như trên
A46: Đẩy truy vấn toàn hàm về chiến dịch Toàn hàm | B46: tháo lắp | C46: Phrase | D46: Warm | Giải pháp | E46: Như trên (giữ ở Research nhóm So sánh)
A47: Đẩy truy vấn địa điểm về chiến dịch Địa điểm | B47: ở đâu | C47: Phrase | D47: Warm | Giải pháp | E47: Truy vấn chọn nơi cần LP3 có chi nhánh, bác sĩ
A48: Đẩy truy vấn địa điểm về chiến dịch Địa điểm | B48: gần đây | C48: Phrase | D48: Warm | Giải pháp | E48: Như trên
A49: Đẩy truy vấn địa điểm về chiến dịch Địa điểm | B49: uy tín | C49: Phrase | D49: Warm | Giải pháp | E49: Như trên
A50: Đẩy truy vấn địa điểm về chiến dịch Địa điểm | B50: hà nội | C50: Phrase | D50: Warm | Giải pháp | E50: Như trên
... A53: Tách nhóm giá rẻ | B53: rẻ | C53: Broad | D53: Hot | Giá: nhóm Giá chung, Trả góp & ưu đãi (cấp nhóm QC) | E53: Để truy vấn 'rẻ' chỉ vào nhóm Giá rẻ, đo riêng chất lượng
A55: C. Quy trình cập nhật
A56: Tuần 1-2: xem báo cáo Cụm từ tìm kiếm hằng ngày. Từ tuần 3: 2 lần/tuần. Thêm phủ định mới vào đúng nhóm trên và ghi lý do.

Sheet 4. Hành trình KH
A1: Giai đoạn | B1: Tâm lý chính | C1: Chiến dịch | D1: Từ khoá đại diện | E1: Thông điệp quảng cáo | F1: Landing page | G1: Chuyển đổi đo lường | H1: Hành động sau lead (Caresoft) | I1: KPI giai đoạn | J1: Bước tiếp theo
A2: 1. Cold: nhận biết vấn đề | B2: Chưa biết implant. Lo ăn nhai kém, ngại chỗ trống | C2: Cold | Vấn đề mất răng | D2: mất răng phải làm sao | E2: Mất răng lâu gây tiêu xương. Kiểm tra sớm để giữ xương hàm | F2: LP8 | G2: Hoàn thành quiz, để lại SĐT | H2: Tag Cold-Mất răng. Zalo nội dung giáo dục 3 lần trong 14 ngày | I2: Chi phí/quiz, % quiz thành lead | J2: Remarketing (RLSA) sang Research và Warm
A3: 2. Consideration: tìm hiểu, so sánh | B3: Sợ đau, sợ biến chứng, sợ chọn sai bác sĩ | C3: Research | Cân nhắc; Warm | Hãng trụ | D3: trồng răng implant có đau không | E3: Bác sĩ trả lời trực tiếp, quy trình rõ từng bước, case thật | F3: LP7, LP6 | G3: Form hỏi bác sĩ, bấm Zalo | H3: Gọi trong 15 phút. Gửi case tương tự tình trạng KH | I3: Lead → lịch hẹn | J3: Mời chụp CT đánh giá xương
A4: 3. Warm: đã chọn implant | B4: Đang so nơi làm và bác sĩ | C4: Warm | Giải pháp Implant; Toàn hàm (Người cao tuổi) | D4: trồng răng implant | E4: Bác sĩ chuyên sâu implant, case thật, bảo hành chính hãng | F4: LP5 | G4: Form đặt lịch, cuộc gọi ≥ 60 giây | H4: Gọi trong 5 phút. Đặt lịch khám + chụp CT | I4: Lead → lịch hẹn ≥ 45% | J4: Xác nhận lịch
A5: 4. Hot: sẵn sàng mua | B5: So giá, tìm nơi gần, cần trả góp | C5: Hot | Giá; Hot | Địa điểm; Hot | Toàn hàm | D5: giá trồng răng implant; all on 4 | E5: Giá minh bạch theo hãng, trả góp, ưu đãi có thời hạn | F5: LP2, LP3, LP4 | G5: Cuộc gọi ≥ 60 giây, form đặt lịch | H5: Gọi trong 5 phút. Nhắc lịch 24h và 2h trước giờ hẹn | I5: Show-up ≥ 65% | J5: Khám và tư vấn tại chi nhánh
A6: 5. Quyết định: kiểm tra thương hiệu | B6: Đã biết NKP, kiểm tra uy tín lần cuối | C6: Brand | Implant | D6: nha khoa paris implant | E6: Bác sĩ, chi nhánh, cam kết bảo hành | F6: LP1 | G6: Đặt lịch | H6: Ưu tiên gọi trước mọi lead khác | I6: Top IS brand ≥ 90% | J6: Khám
A7: 6. Khám và chốt (offline) | B7: Lo tổng chi phí, cần người nhà đồng ý | C7: Không chạy QC | E7: Kế hoạch điều trị in, báo giá trọn gói, phương án trả góp | F7: Phòng tư vấn | G7: Ca chốt + doanh thu (import offline vào Google Ads qua GCLID) | H7: Chưa chốt: follow-up D1, D3, D7, D30. Mời người nhà cùng tư vấn | I7: Tỷ lệ chốt, giá trị ca | J7: Điều trị
A8: 7. Sau implant: LTV và giới thiệu | B8: Hài lòng, cần chăm sóc dài hạn | C8: CRM (không dùng Search) | E8: Chăm sóc trụ, ưu đãi người thân | F8: Zalo OA | G8: Tái khám, lượt giới thiệu | H8: Tái khám 6 tháng, bọc sứ răng kế cận, cạo vôi định kỳ, chương trình giới thiệu người thân | I8: Doanh thu tái mua/KH, tỷ lệ giới thiệu | J8: Cross-sell: răng sứ, chỉnh nha cho con cháu, dịch vụ khác trong hệ sinh thái HCI
A10: LANDING PAGE | B10: Nội dung bắt buộc | C10: CTA chính
A11: LP1: Implant thương hiệu NKP | B11: Bác sĩ implant, số ca, chi nhánh, bảo hành, đánh giá KH | C11: Đặt lịch khám
A12: LP2: Bảng giá + trả góp | B12: Giá theo hãng trụ, gồm những gì, trả góp, ưu đãi có hạn | C12: Nhận báo giá theo tình trạng
A13: LP3: Chi nhánh + bác sĩ | B13: Bản đồ, giờ làm việc, hồ sơ bác sĩ từng chi nhánh, case thật | C13: Gọi chi nhánh gần nhất
A14: LP4: Toàn hàm All-on-4/6 | B14: Trước/sau ca toàn hàm, quy trình, báo giá trọn gói, trả góp, thông điệp cho con cái mua hộ | C14: Tư vấn 1:1 với bác sĩ
A15: LP5: Implant đơn lẻ | B15: Case theo vị trí răng, quy trình, thời gian, bảo hành | C15: Đặt lịch khám + chụp CT
A16: LP6: So sánh hãng trụ | B16: Bảng so sánh các hãng NKP đang dùng, giá, bảo hành | C16: Tư vấn trụ phù hợp
A17: LP7: Hỏi đáp bác sĩ | B17: FAQ: đau không, bao lâu, bệnh nền, so sánh cầu răng | C17: Hỏi bác sĩ qua Zalo
A18: LP8: Quiz tình trạng mất răng | B18: 5 câu hỏi, kết quả gợi ý giải pháp, thu SĐT ở bước cuối | C18: Nhận kết quả và tư vấn

Sheet 5. Giá thầu & Tối ưu
A1: A. CHẤM ĐIỂM ƯU TIÊN CHIẾN DỊCH
A2: Điểm = Ý định mua × Giá trị ca × Khả năng chốt (thang 1-5). Điểm ban đầu là đánh giá chuyên môn, cập nhật hằng tháng bằng tỷ lệ chốt thực tế từ Caresoft.
A3: Chiến dịch | B3: Ý định mua (1-5) | C3: Giá trị ca (1-5) | D3: Khả năng chốt (1-5) | E3: Điểm ưu tiên | F3: Xếp hạng | G3: Chiến lược giá thầu khởi đầu | H3: Chỉ tiêu cạnh tranh
A4: ='1. Tổng quan'!A9 -> NKP | Brand | Implant | B4: 5 | C4: 3 | D4: 5 | E4: =B4*C4*D4 -> 75 | F4: =RANK(E4,$E$4:$E$12) -> 1 | G4: Target Impression Share (đầu trang) | H4: Top IS ≥ 90%
A5: ='1. Tổng quan'!A10 -> NKP | Hot | Giá Implant | B5: 5 | C5: 3 | D5: 4 | E5: =B5*C5*D5 -> 60 | F5: =RANK(E5,$E$4:$E$12) -> 2 | G5: Max Conversions → tCPA | H5: Top IS ≥ 60%
A6: ='1. Tổng quan'!A11 -> NKP | Hot | Địa điểm | B6: 5 | C6: 3 | D6: 4 | E6: =B6*C6*D6 -> 60 | F6: =RANK(E6,$E$4:$E$12) -> 2 | G6: Max Conversions → tCPA | H6: Top IS ≥ 60%
A7: ='1. Tổng quan'!A12 -> NKP | Hot | Toàn hàm | B7: 4 | C7: 5 | D7: 3 | E7: =B7*C7*D7 -> 60 | F7: =RANK(E7,$E$4:$E$12) -> 2 | G7: Max Conversions → Max Conversion Value | H7: Top IS ≥ 60%, chấp nhận CPC cao hơn nhóm Giá
A8: ='1. Tổng quan'!A13 -> NKP | Warm | Giải pháp Implant | B8: 3 | C8: 3 | D8: 3 | E8: =B8*C8*D8 -> 27 | F8: =RANK(E8,$E$4:$E$12) -> 6 | G8: tCPA khi đủ dữ liệu | H8: Không đặt chỉ tiêu IS
A9: ='1. Tổng quan'!A14 -> NKP | Warm | Hãng trụ | B9: 3 | C9: 4 | D9: 3 | E9: =B9*C9*D9 -> 36 | F9: =RANK(E9,$E$4:$E$12) -> 5 | G9: tCPA khi đủ dữ liệu | H9: Không đặt chỉ tiêu IS
A10: ='1. Tổng quan'!A15 -> NKP | Research | Cân nhắc | B10: 2 | C10: 3 | D10: 2 | E10: =B10*C10*D10 -> 12 | F10: =RANK(E10,$E$4:$E$12) -> 8 | G10: Max Clicks có trần CPC | H10: Không đặt chỉ tiêu IS
A11: ='1. Tổng quan'!A16 -> NKP | Cold | Vấn đề mất răng | B11: 1 | C11: 4 | D11: 1 | E11: =B11*C11*D11 -> 4 | F11: =RANK(E11,$E$4:$E$12) -> 9 | G11: Max Clicks trần CPC thấp | H11: Không đặt chỉ tiêu IS
A12: ='1. Tổng quan'!A17 -> NKP | Test | Đối thủ | B12: 3 | C12: 3 | D12: 2 | E12: =B12*C12*D12 -> 18 | F12: =RANK(E12,$E$4:$E$12) -> 7 | G12: Manual CPC | H12: Không đua vị trí
A14: B. NGƯỠNG QUẢN TRỊ GIÁ THẦU
A15: Chỉ số | B15: Giá trị (VND) | C15: Ghi chú
A16: CPL mục tiêu | B16: ='1. Tổng quan'!B41 -> 275000 | C16: Lấy từ mô hình phễu tab 1
A17: Chi phí / ca chốt mục tiêu | B17: ='1. Tổng quan'!B42 -> 2089268.8 | C17: Lấy từ mô hình phễu tab 1
A18: Giá trị gán cho 1 lịch hẹn | B18: ='1. Tổng quan'!B33*'1. Tổng quan'!B31*'1. Tổng quan'!B32 -> 8775000 | C18: Dùng khi import chuyển đổi offline (Pha 3)
A19: Giá trị gán cho 1 lead | B19: =B18*'1. Tổng quan'!B30 -> 3948750 | C19: Dùng khi import chuyển đổi offline (Pha 3)
A21: Quy tắc | B21: Hệ số | C21: Ngưỡng (VND) | D21: Hành động
A22: Từ khoá chi tiêu vượt ngưỡng mà 0 lead | B22: 2 | C22: =B22*$B$16 -> 550000 | D22: Tạm dừng từ khoá, kiểm tra search terms và LP
A23: CPL chiến dịch vượt ngưỡng 7 ngày liên tục | B23: 1.3 | C23: =B23*$B$16 -> 357500 | D23: Giảm tCPA/giá thầu 15%, rà lại phủ định
A24: CPL dưới ngưỡng và mất IS do ngân sách > 20% | B24: 0.8 | C24: =B24*$B$16 -> 220000 | D24: Tăng ngân sách 20%, tối đa 1 lần/7 ngày
A25: Chi phí/ca chốt vượt ngưỡng 30 ngày | B25: 1.3 | C25: =B25*$B$17 -> 2716049.4 | D25: Rà chất lượng lead theo từ khoá cùng Sales, cắt nhóm kém
A27: C. LỘ TRÌNH CHIẾN LƯỢC GIÁ THẦU 3 PHA
A28: Pha | B28: Thời gian | C28: Điều kiện chuyển pha | D28: Chiến lược giá thầu | E28: Chuyển đổi tối ưu | F28: Việc bắt buộc
A29: Pha 1: Học | B29: Tuần 1-3 | C29: Bắt đầu | D29: P1: Max Conversions chưa đặt tCPA. Brand: Target IS. P3-P4: Max Clicks có trần CPC | E29: Lead (form, cuộc gọi ≥ 60 giây, Zalo có SĐT) | F29: Xem search terms hằng ngày, kiểm tra tag, ghi GCLID vào Caresoft
A30: Pha 2: Ổn định | B30: Tuần 4-8 | C30: ≥ 30 chuyển đổi/30 ngày/chiến dịch | D30: tCPA = CPL thực tế × 1,1. Mỗi lần chỉnh ±15%, cách nhau ≥ 7 ngày | E30: Lead + Lịch hẹn | F30: Import lịch hẹn từ Caresoft hằng ngày
A31: Pha 3: Tối ưu doanh thu | B31: Từ tuần 9 | C31: Đủ dữ liệu lịch hẹn và ca chốt có GCLID | D31: Max Conversion Value / tROAS với giá trị ở mục B | E31: Lịch hẹn, Đến khám, Ca chốt + doanh thu | F31: Thử Broad match + audience signal ở 1 chiến dịch, so với Phrase/Exact
A33: D. QUY TẮC CẠNH TRANH
A34: Hạng mục | B34: Quy tắc
A35: Brand | B35: Giữ Top IS ≥ 90%. Nếu Auction Insights cho thấy đối thủ đấu thầu tên NKP, nâng trần CPC brand ngay.
A36: Hot (Giá, Địa điểm) | B36: Top IS ≥ 60%. Xem Auction Insights hằng tuần. Không đua vị trí 1 khi CPL vượt ngưỡng mục B.
A37: Toàn hàm | B37: Được chấp nhận CPL cao hơn các chiến dịch khác vì giá trị ca cao hơn nhiều lần. Đánh giá bằng ROAS, không bằng CPL.
A38: Lịch chạy | B38: Dồn ngân sách vào giờ tổng đài trực. Ngoài giờ chỉ nhận form và gọi lại trước 9h sáng.
A39: Vị trí | B39: Nhắm bán kính quanh chi nhánh, chọn 'Người ở hoặc thường xuyên ở'. Loại vùng xa có show-up thấp.
A40: Thiết bị | B40: Mobile: bật asset cuộc gọi và địa điểm. Cuộc gọi ≥ 60 giây tính là chuyển đổi.
A41: Mạng hiển thị | B41: Tắt Search Partners và Display trên mọi chiến dịch Search.
A42: Đối tượng | B42: Thêm audience dạng Observation: đã vào LP chưa để lead, lead chưa chốt. Dùng làm tín hiệu cho Smart Bidding.
A43: Mùa vụ | B43: Đẩy ngân sách T10 và T12 (Việt kiều về Tết), giảm giữa T8-T9. Kiểm chứng bằng dữ liệu NKP các năm trước.
A44: Tốc độ phản hồi | B44: Lead Hot gọi trong 5 phút. Nếu tổng đài quá tải ở khung giờ nào, giảm ngân sách khung đó thay vì để lead nguội.
...
